Workbook

Sheet Intro
B2: Made by: | D2: Grigoryev Vladimir
D3: Karaev Nadir
D4: Varochka Dmitry
D5: Karpushkina Ekaterina
D6: Zakharova Elizaveta
D7: Uskova Olga
D8: Cherniy Nikita
D9: Sharafutdinov Ilia
D10: Kulikov Igor
D11: Smirnova Anastasia
B13: Object of valuation: | D13: Mercedes-Benz Group AG
B15: Methods of valuation: | D15: Income approach
D16: Market approach
B18: Est. price (mln EUR): | D18: =Results!D9*Ratios!D4 -> 64671.515
B19: Est. price per share (EUR): | D19: =Results!D9 -> 67.163014

Sheet Legend
B2: Table of contents:
B17: Legend:
B19: xxx | D19: Assumptions with source
B21: xxx | D21: Analytical assumption
B23: xxx | D23: Change in formula
B25: xxx | D25: Link from other sheet
B27: xxx | D27: Analysis
B29: xxx | D29: Analysis %

Sheet Overview & Results
B2: Main results of preliminary analysis
B4: Sharp profitablity decline
B5: FY2025 marked the sharpest profitability decline since the COVID era. Revenue fell 9.2% year-on-year to €132.2 billion, while EBIT collapsed from €13.6 billion to €5.8 billion — compressing EBIT margin from 9.3% to 4.4%. Net profit dropped 48.8% to €5.3 billion. Three structural headwinds converged simultaneously: US tariff escalation raising cost of sales, a 29% volume decline in China amid intensifying competition from domestic EV players, and €1.6 billion in one-off restructuring charges under the "Next Level Performance" programme launched in April 2025.
B19: Company hold strong in terms of financial endurance
B20: The balance sheet remains solid despite earnings pressure. Total equity stands at €94.2 billion (36.9% of total assets), and operating cash flow of €18.0 billion comfortably covers capital expenditure of €9.7 billion, dividends of €4.3 billion, and share buybacks of €0.4 billion. The group maintains €19.8 billion in liquidity and an undrawn €11 billion syndicated credit facility extended through 2030. Total financial debt of ~€100 billion is structurally elevated but largely attributable to Mercedes-Benz Financial Services — a captive finance arm whose debt is matched by corresponding lease and loan receivables, and should not be conflated with industrial leverage.
B34: Dividends reflect unsertanty
B35: Dividend policy reflects management's commitment to shareholder returns even under stress. The FY2025 dividend of €3.50 per share implies a payout ratio of ~80% — well above the company's stated ~40% target — signalling a deliberate effort to cushion investor sentiment rather than preserve capital. While sustainable in the near term given the cash flow profile, this approach limits balance sheet flexibility if the earnings recovery takes longer than expected.
B46: Main logic implied in valuation
B47: Valuation analysis suggests meaningful upside on a normalised earnings basis. Our weighted blended valuation across six methodologies — Comparables (30%), DCF FCFE (30%), DDM 1-step (15%), DDM H-model (10%), DCF FCFF (10%), and DDM 2-step (5%) — yields an estimated intrinsic value of €67.16 per share, implying 28.7% upside to the current market price. DDM models, which anchor to the dividend stream, converge around €52–59 and broadly confirm the current market price as fair value at depressed earnings. FCFE and FCFF models price in a recovery of EBITDA margins toward 16–17% by 2028, driven by the ramp-up of the new CLA electric platform, the MB.OS software ecosystem, and gradual tariff normalisation — a scenario achievable but not without execution risk.

Sheet Template
F5: Source | G5: UoM | I5: Const | J5: 2021A | K5: 2022A | L5: 2023A | M5: 2024A | N5: 2025A | O5: 2026F | P5: 2027F | Q5: 2028F | R5: 2029F | S5: 2030F
B7: Heading
C9: Subheading
D11: Text

Sheet 1. Core

Sheet BS
A5: Balance sheet | F5: Source | G5: UoM | I5: Const | J5: 2021A | K5: 2022A | L5: 2023A | M5: 2024A | N5: 2025A
B7: Assets
C9: Non-current assets
D11: Intangible assets | F11: Annual statement | G11: =IF(M11="","",IF(AND(M11>=-1,M11<=1), "%","mln EUR")) -> mln EUR | J11: 15005 | K11: 15869 | L11: 17593 | M11: 19436 | N11: 20547
E12: Change YoY | F12: Calcs | G12: =IF(M12="","",IF(AND(M12>=-1,M12<=1), "%","mln EUR")) -> % | K12: =IFERROR(K11/J11-1, "-") -> 0.057580806 | L12: =IFERROR(L11/K11-1, "-") -> 0.10863949 | M12: =IFERROR(M11/L11-1, "-") -> 0.10475757 | N12: =IFERROR(N11/M11-1, "-") -> 0.057161967
G13: =IF(M13="","",IF(AND(M13>=-1,M13<=1), "%","mln EUR"))
D14: Property, plant and equipment including right-of-use assets | F14: Annual statement | G14: =IF(M14="","",IF(AND(M14>=-1,M14<=1), "%","mln EUR")) -> mln EUR | J14: 27859 | K14: 27250 | L14: 26090 | M14: 26537 | N14: 27340
E15: Change YoY | F15: Calcs | G15: =IF(M15="","",IF(AND(M15>=-1,M15<=1), "%","mln EUR")) -> % | K15: =IFERROR(K14/J14-1, "-") -> -0.021860081 | L15: =IFERROR(L14/K14-1, "-") -> -0.042568807 | M15: =IFERROR(M14/L14-1, "-") -> 0.017133001 | N15: =IFERROR(N14/M14-1, "-") -> 0.030259637
G16: =IF(M16="","",IF(AND(M16>=-1,M16<=1), "%","mln EUR"))
D17: Equipment on operating leases | F17: Annual statement | G17: =IF(M17="","",IF(AND(M17>=-1,M17<=1), "%","mln EUR")) -> mln EUR | J17: 44471 | K17: 41552 | L17: 41712 | M17: 45220 | N17: 39472
E18: Change YoY | F18: Calcs | G18: =IF(M18="","",IF(AND(M18>=-1,M18<=1), "%","mln EUR")) -> % | K18: =IFERROR(K17/J17-1, "-") -> -0.065638281 | L18: =IFERROR(L17/K17-1, "-") -> 0.0038505968 | M18: =IFERROR(M17/L17-1, "-") -> 0.084100499 | N18: =IFERROR(N17/M17-1, "-") -> -0.1271119
G19: =IF(M19="","",IF(AND(M19>=-1,M19<=1), "%","mln EUR"))
D20: Equity-method investments | F20: Annual statement | G20: =IF(M20="","",IF(AND(M20>=-1,M20<=1), "%","mln EUR")) -> mln EUR | J20: 13588 | K20: 13530 | L20: 13104 | M20: 12786 | N20: 10037
E21: Change YoY | F21: Calcs | G21: =IF(M21="","",IF(AND(M21>=-1,M21<=1), "%","mln EUR")) -> % | K21: =IFERROR(K20/J20-1, "-") -> -0.0042684722 | L21: =IFERROR(L20/K20-1, "-") -> -0.031485588 | M21: =IFERROR(M20/L20-1, "-") -> -0.024267399 | N21: =IFERROR(N20/M20-1, "-") -> -0.21500078
G22: =IF(M22="","",IF(AND(M22>=-1,M22<=1), "%","mln EUR"))
D23: Receivables from financial services | F23: Annual statement | G23: =IF(M23="","",IF(AND(M23>=-1,M23<=1), "%","mln EUR")) -> mln EUR | J23: 46955 | K23: 48237 | L23: 49742 | M23: 48547 | N23: 41902
E24: Change YoY | F24: Calcs | G24: =IF(M24="","",IF(AND(M24>=-1,M24<=1), "%","mln EUR")) -> % | K24: =IFERROR(K23/J23-1, "-") -> 0.027302737 | L24: =IFERROR(L23/K23-1, "-") -> 0.031200116 | M24: =IFERROR(M23/L23-1, "-") -> -0.024023964 | N24: =IFERROR(N23/M23-1, "-") -> -0.13687766
G25: =IF(M25="","",IF(AND(M25>=-1,M25<=1), "%","mln EUR"))
D26: Marketable debt securities and similar investments | F26: Annual statement | G26: =IF(M26="","",IF(AND(M26>=-1,M26<=1), "%","mln EUR")) -> mln EUR | J26: 873 | K26: 823 | L26: 699 | M26: 644 | N26: 626
E27: Change YoY | F27: Calcs | G27: =IF(M27="","",IF(AND(M27>=-1,M27<=1), "%","mln EUR")) -> % | K27: =IFERROR(K26/J26-1, "-") -> -0.057273769 | L27: =IFERROR(L26/K26-1, "-") -> -0.15066829 | M27: =IFERROR(M26/L26-1, "-") -> -0.078683834 | N27: =IFERROR(N26/M26-1, "-") -> -0.027950311
G28: =IF(M28="","",IF(AND(M28>=-1,M28<=1), "%","mln EUR"))
D29: Other financial assets | F29: Annual statement | G29: =IF(M29="","",IF(AND(M29>=-1,M29<=1), "%","mln EUR")) -> mln EUR | J29: 3181 | K29: 4478 | L29: 4340 | M29: 3020 | N29: 2953
E30: Change YoY | F30: Calcs | G30: =IF(M30="","",IF(AND(M30>=-1,M30<=1), "%","mln EUR")) -> % | K30: =IFERROR(K29/J29-1, "-") -> 0.40773342 | L30: =IFERROR(L29/K29-1, "-") -> -0.030817329 | M30: =IFERROR(M29/L29-1, "-") -> -0.30414747 | N30: =IFERROR(N29/M29-1, "-") -> -0.02218543
G31: =IF(M31="","",IF(AND(M31>=-1,M31<=1), "%","mln EUR"))
D32: Deferred tax assets | F32: Annual statement | G32: =IF(M32="","",IF(AND(M32>=-1,M32<=1), "%","mln EUR")) -> mln EUR | J32: 3434 | K32: 3725 | L32: 4127 | M32: 4335 | N32: 6090
E33: Change YoY | F33: Calcs | G33: =IF(M33="","",IF(AND(M33>=-1,M33<=1), "%","mln EUR")) -> % | K33: =IFERROR(K32/J32-1, "-") -> 0.084740827 | L33: =IFERROR(L32/K32-1, "-") -> 0.10791946 | M33: =IFERROR(M32/L32-1, "-") -> 0.050399806 | N33: =IFERROR(N32/M32-1, "-") -> 0.40484429
G34: =IF(M34="","",IF(AND(M34>=-1,M34<=1), "%","mln EUR"))
D35: Income tax assets | F35: Annual statement | G35: =IF(M35="","",IF(AND(M35>=-1,M35<=1), "%","mln EUR")) -> mln EUR | J35: 0 | K35: 0 | L35: 318 | M35: 327 | N35: 426
E36: Change YoY | F36: Calcs | G36: =IF(M36="","",IF(AND(M36>=-1,M36<=1), "%","mln EUR")) -> % | K36: =IFERROR(K35/J35-1, "-") -> - | L36: =IFERROR(L35/K35-1, "-") -> - | M36: =IFERROR(M35/L35-1, "-") -> 0.028301887 | N36: =IFERROR(N35/M35-1, "-") -> 0.30275229
G37: =IF(M37="","",IF(AND(M37>=-1,M37<=1), "%","mln EUR"))
D38: Other assets | F38: Annual statement | G38: =IF(M38="","",IF(AND(M38>=-1,M38<=1), "%","mln EUR")) -> mln EUR | J38: 1536 | K38: 1677 | L38: 1265 | M38: 2391 | N38: 3941
E39: Change YoY | F39: Calcs | G39: =IF(M39="","",IF(AND(M39>=-1,M39<=1), "%","mln EUR")) -> % | K39: =IFERROR(K38/J38-1, "-") -> 0.091796875 | L39: =IFERROR(L38/K38-1, "-") -> -0.2456768 | M39: =IFERROR(M38/L38-1, "-") -> 0.89011858 | N39: =IFERROR(N38/M38-1, "-") -> 0.64826432
C41: Total non-current assets
D43: Total non-current assets | F43: Calcs | G43: =IF(M43="","",IF(AND(M43>=-1,M43<=1), "%","mln EUR")) -> mln EUR | J43: =SUM(J11,J14,J17,J20,J23,J26,J29,J32,J35,J38,) -> 156902 | K43: =SUM(K11,K14,K17,K20,K23,K26,K29,K32,K35,K38,) -> 157141 | L43: =SUM(L11,L14,L17,L20,L23,L26,L29,L32,L35,L38,) -> 158990 | M43: =SUM(M11,M14,M17,M20,M23,M26,M29,M32,M35,M38,) -> 163243 | N43: =SUM(N11,N14,N17,N20,N23,N26,N29,N32,N35,N38,) -> 153334
E44: Change YoY | F44: Calcs | G44: =IF(M44="","",IF(AND(M44>=-1,M44<=1), "%","mln EUR")) -> % | K44: =IFERROR(K43/J43-1, "-") -> 0.0015232438 | L44: =IFERROR(L43/K43-1, "-") -> 0.011766503 | M44: =IFERROR(M43/L43-1, "-") -> 0.02675011 | N44: =IFERROR(N43/M43-1, "-") -> -0.060700918
C46: Current assets
D48: Inventories | F48: Annual statement | G48: =IF(M48="","",IF(AND(M48>=-1,M48<=1), "%","mln EUR")) -> mln EUR | J48: 21466 | K48: 25621 | L48: 26486 | M48: 26234 | N48: 23933
E49: Change YoY | F49: Calcs | G49: =IF(M49="","",IF(AND(M49>=-1,M49<=1), "%","mln EUR")) -> % | K49: =IFERROR(K48/J48-1, "-") -> 0.19356191 | L49: =IFERROR(L48/K48-1, "-") -> 0.033761368 | M49: =IFERROR(M48/L48-1, "-") -> -0.0095144605 | N49: =IFERROR(N48/M48-1, "-") -> -0.087710605
G50: =IF(M50="","",IF(AND(M50>=-1,M50<=1), "%","mln EUR"))
D51: Trade receivables | F51: Annual statement | G51: =IF(M51="","",IF(AND(M51>=-1,M51<=1), "%","mln EUR")) -> mln EUR | J51: 7673 | K51: 8100 | L51: 7281 | M51: 6973 | N51: 5851
...

Sheet PL
A5: Income statement (P&L) | F5: Source | G5: UoM | I5: Const | J5: 2021A | K5: 2022A | L5: 2023A | M5: 2024A | N5: 2025A
B7: Income statement
C9: Income statement
D11: Revenue | F11: Annual statement | G11: =IF(M11="","",IF(AND(M11>=-1,M11<=1), "%","mln EUR")) -> mln EUR | J11: 133893 | K11: 150017 | L11: 152390 | M11: 145594 | N11: 132214
E12: Change YoY | F12: Calcs | G12: =IF(M12="","",IF(AND(M12>=-1,M12<=1), "%","mln EUR")) -> % | K12: =IFERROR(K11/J11-1, "-") -> 0.12042452 | L12: =IFERROR(L11/K11-1, "-") -> 0.015818207 | M12: =IFERROR(M11/L11-1, "-") -> -0.044596102 | N12: =IFERROR(N11/M11-1, "-") -> -0.091899391
G13: =IF(M13="","",IF(AND(M13>=-1,M13<=1), "%","mln EUR"))
D14: Cost of goods sold | F14: Annual statement | G14: =IF(M14="","",IF(AND(M14>=-1,M14<=1), "%","mln EUR")) -> mln EUR | J14: -103218 | K14: -115997 | L14: -117386 | M14: -117018 | N14: -109881
E15: Change YoY | F15: Calcs | G15: =IF(M15="","",IF(AND(M15>=-1,M15<=1), "%","mln EUR")) -> % | K15: =IFERROR(K14/J14-1, "-") -> 0.12380593 | L15: =IFERROR(L14/K14-1, "-") -> 0.011974448 | M15: =IFERROR(M14/L14-1, "-") -> -0.0031349565 | N15: =IFERROR(N14/M14-1, "-") -> -0.060990617
G16: =IF(M16="","",IF(AND(M16>=-1,M16<=1), "%","mln EUR"))
D17: Gross profit | F17: Annual statement | G17: =IF(M17="","",IF(AND(M17>=-1,M17<=1), "%","mln EUR")) -> mln EUR | J17: 30675 | K17: 34020 | L17: 35004 | M17: 28576 | N17: 22333
E18: Change YoY | F18: Calcs | G18: =IF(M18="","",IF(AND(M18>=-1,M18<=1), "%","mln EUR")) -> % | K18: =IFERROR(K17/J17-1, "-") -> 0.10904645 | L18: =IFERROR(L17/K17-1, "-") -> 0.028924162 | M18: =IFERROR(M17/L17-1, "-") -> -0.18363616 | N18: =IFERROR(N17/M17-1, "-") -> -0.21847004
E19: Margin | F19: Calcs | G19: =IF(M19="","",IF(AND(M19>=-1,M19<=1), "%","mln EUR")) -> % | J19: =IFERROR(J17/J11, "-") -> 0.22910085 | K19: =IFERROR(K17/K11, "-") -> 0.2267743 | L19: =IFERROR(L17/L11, "-") -> 0.22970011 | M19: =IFERROR(M17/M11, "-") -> 0.19627182 | N19: =IFERROR(N17/N11, "-") -> 0.16891555
G20: =IF(M20="","",IF(AND(M20>=-1,M20<=1), "%","mln EUR"))
D21: Selling expenses | F21: Annual statement | G21: =IF(M21="","",IF(AND(M21>=-1,M21<=1), "%","mln EUR")) -> mln EUR | J21: -9194 | K21: -9482 | L21: -10270 | M21: -9993 | N21: -9718
E22: Change YoY | F22: Calcs | G22: =IF(M22="","",IF(AND(M22>=-1,M22<=1), "%","mln EUR")) -> % | K22: =IFERROR(K21/J21-1, "-") -> 0.031324777 | L22: =IFERROR(L21/K21-1, "-") -> 0.08310483 | M22: =IFERROR(M21/L21-1, "-") -> -0.026971762 | N22: =IFERROR(N21/M21-1, "-") -> -0.027519263
G23: =IF(M23="","",IF(AND(M23>=-1,M23<=1), "%","mln EUR"))
D24: General administrative expenses | F24: Annual statement | G24: =IF(M24="","",IF(AND(M24>=-1,M24<=1), "%","mln EUR")) -> mln EUR | J24: -2808 | K24: -2584 | L24: -2771 | M24: -2529 | N24: -2477
E25: Change YoY | F25: Calcs | G25: =IF(M25="","",IF(AND(M25>=-1,M25<=1), "%","mln EUR")) -> % | K25: =IFERROR(K24/J24-1, "-") -> -0.07977208 | L25: =IFERROR(L24/K24-1, "-") -> 0.072368421 | M25: =IFERROR(M24/L24-1, "-") -> -0.087333093 | N25: =IFERROR(N24/M24-1, "-") -> -0.020561487
G26: =IF(M26="","",IF(AND(M26>=-1,M26<=1), "%","mln EUR"))
D27: Research and non-capitalized development costs | F27: Annual statement | G27: =IF(M27="","",IF(AND(M27>=-1,M27<=1), "%","mln EUR")) -> mln EUR | J27: -5467 | K27: -5602 | L27: -6230 | M27: -5580 | N27: -6055
E28: Change YoY | F28: Calcs | G28: =IF(M28="","",IF(AND(M28>=-1,M28<=1), "%","mln EUR")) -> % | K28: =IFERROR(K27/J27-1, "-") -> 0.024693616 | L28: =IFERROR(L27/K27-1, "-") -> 0.11210282 | M28: =IFERROR(M27/L27-1, "-") -> -0.10433387 | N28: =IFERROR(N27/M27-1, "-") -> 0.085125448
G29: =IF(M29="","",IF(AND(M29>=-1,M29<=1), "%","mln EUR"))
D30: Other operating income/expense | F30: Annual statement | G30: =IF(M30="","",IF(AND(M30>=-1,M30<=1), "%","mln EUR")) -> mln EUR | J30: 1153 | K30: 2034 | L30: 1690 | M30: 2024 | N30: 526
E31: Change YoY | F31: Calcs | G31: =IF(M31="","",IF(AND(M31>=-1,M31<=1), "%","mln EUR")) -> % | K31: =IFERROR(K30/J30-1, "-") -> 0.76409367 | L31: =IFERROR(L30/K30-1, "-") -> -0.16912488 | M31: =IFERROR(M30/L30-1, "-") -> 0.19763314 | N31: =IFERROR(N30/M30-1, "-") -> -0.74011858
G32: =IF(M32="","",IF(AND(M32>=-1,M32<=1), "%","mln EUR"))
D33: Gains/losses on equity-method invesments, net | F33: Annual statement | G33: =IF(M33="","",IF(AND(M33>=-1,M33<=1), "%","mln EUR")) -> mln EUR | J33: 1352 | K33: 1732 | L33: 2129 | M33: 1138 | N33: 1118
E34: Change YoY | F34: Calcs | G34: =IF(M34="","",IF(AND(M34>=-1,M34<=1), "%","mln EUR")) -> % | K34: =IFERROR(K33/J33-1, "-") -> 0.28106509 | L34: =IFERROR(L33/K33-1, "-") -> 0.22921478 | M34: =IFERROR(M33/L33-1, "-") -> -0.46547675 | N34: =IFERROR(N33/M33-1, "-") -> -0.017574692
G35: =IF(M35="","",IF(AND(M35>=-1,M35<=1), "%","mln EUR"))
D36: Other financial income/expense, net | F36: Annual statement | G36: =IF(M36="","",IF(AND(M36>=-1,M36<=1), "%","mln EUR")) -> mln EUR | J36: 317 | K36: 340 | L36: 108 | M36: -37 | N36: 93
E37: Change YoY | F37: Calcs | G37: =IF(M37="","",IF(AND(M37>=-1,M37<=1), "%","mln EUR")) -> mln EUR | K37: =IFERROR(K36/J36-1, "-") -> 0.072555205 | L37: =IFERROR(L36/K36-1, "-") -> -0.68235294 | M37: =IFERROR(M36/L36-1, "-") -> -1.3425926 | N37: =IFERROR(N36/M36-1, "-") -> -3.5135135
G38: =IF(M38="","",IF(AND(M38>=-1,M38<=1), "%","mln EUR"))
D39: EBIT | F39: Annual statement | G39: =IF(M39="","",IF(AND(M39>=-1,M39<=1), "%","mln EUR")) -> mln EUR | J39: 16028 | K39: 20458 | L39: 19660 | M39: 13599 | N39: 5820
E40: Change YoY | F40: Calcs | G40: =IF(M40="","",IF(AND(M40>=-1,M40<=1), "%","mln EUR")) -> % | K40: =IFERROR(K39/J39-1, "-") -> 0.27639132 | L40: =IFERROR(L39/K39-1, "-") -> -0.039006746 | M40: =IFERROR(M39/L39-1, "-") -> -0.30829095 | N40: =IFERROR(N39/M39-1, "-") -> -0.57202735
E41: Margin | F41: Calcs | G41: =IF(M41="","",IF(AND(M41>=-1,M41<=1), "%","mln EUR")) -> % | J41: =IFERROR(J39/J11, "-") -> 0.11970753 | K41: =IFERROR(K39/K11, "-") -> 0.13637121 | L41: =IFERROR(L39/L11, "-") -> 0.12901109 | M41: =IFERROR(M39/M11, "-") -> 0.093403574 | N41: =IFERROR(N39/N11, "-") -> 0.044019544
G42: =IF(M42="","",IF(AND(M42>=-1,M42<=1), "%","mln EUR"))
D43: Interest income | F43: Annual statement | G43: =IF(M43="","",IF(AND(M43>=-1,M43<=1), "%","mln EUR")) -> mln EUR | J43: -217 | K43: -154 | L43: 424 | M43: 548 | N43: 464
E44: Change YoY | F44: Calcs | G44: =IF(M44="","",IF(AND(M44>=-1,M44<=1), "%","mln EUR")) -> % | K44: =IFERROR(K43/J43-1, "-") -> -0.29032258 | L44: =IFERROR(L43/K43-1, "-") -> -3.7532468 | M44: =IFERROR(M43/L43-1, "-") -> 0.29245283 | N44: =IFERROR(N43/M43-1, "-") -> -0.15328467
G45: =IF(M45="","",IF(AND(M45>=-1,M45<=1), "%","mln EUR"))
D46: Profit before income taxes | F46: Annual statement | G46: =IF(M46="","",IF(AND(M46>=-1,M46<=1), "%","mln EUR")) -> mln EUR | J46: 15811 | K46: 20304 | L46: 20084 | M46: 14147 | N46: 6284
E47: Change YoY | F47: Calcs | G47: =IF(M47="","",IF(AND(M47>=-1,M47<=1), "%","mln EUR")) -> % | K47: =IFERROR(K46/J46-1, "-") -> 0.28416925 | L47: =IFERROR(L46/K46-1, "-") -> -0.010835303 | M47: =IFERROR(M46/L46-1, "-") -> -0.29560844 | N47: =IFERROR(N46/M46-1, "-") -> -0.55580688
...

Sheet CF
A5: Cashflow statement | F5: Source | G5: UoM | I5: Const | J5: 2021A | K5: 2022A | L5: 2023A | M5: 2024A | N5: 2025A
B7: Cash and cash equivalents
C9: Cash and cash equivalents at beginning of period
D11: Cash and cash equivalents ta beginning of period | F11: Annual statement | G11: =IF(M11="","",IF(AND(M11>=-1,M11<=1), "%","mln EUR")) -> mln EUR | J11: 23048 | K11: 23182 | L11: 17679 | M11: 15972 | N11: 14516
D12: less cash and cash equivalents classified as assets held for sale at beginning of year | F12: Annual statement | G12: =IF(M12="","",IF(AND(M12>=-1,M12<=1), "%","mln EUR")) -> mln EUR | J12: 0 | K12: 0 | L12: 0 | M12: 10 | N12: 5
G13: =IF(M13="","",IF(AND(M13>=-1,M13<=1), "%","mln EUR"))
D14: Cash and cash equivalents at beginning of year (Consolidated Statement of Financial Position) | F14: Annual statement | G14: =IF(M14="","",IF(AND(M14>=-1,M14<=1), "%","mln EUR")) -> mln EUR | J14: 23048 | K14: 23182 | L14: 17679 | M14: 15962 | N14: 14511
G15: =IF(M15="","",IF(AND(M15>=-1,M15<=1), "%","mln EUR"))
B16: Cashflow from operating activities
G17: =IF(M17="","",IF(AND(M17>=-1,M17<=1), "%","mln EUR"))
C18: Profit from continuing operations
G19: =IF(M19="","",IF(AND(M19>=-1,M19<=1), "%","mln EUR"))
D20: Profit from continuing operations | F20: Annual statement | G20: =IF(M20="","",IF(AND(M20>=-1,M20<=1), "%","mln EUR")) -> mln EUR | J20: 28775 | K20: 20304 | L20: 20084 | M20: 14147 | N20: 6284
D21: Depreciation and amortisation/impairments | F21: Annual statement | G21: =IF(M21="","",IF(AND(M21>=-1,M21<=1), "%","mln EUR")) -> mln EUR | J21: 6980 | K21: 6521 | L21: 6663 | M21: 6772 | N21: 7223
D22: Other non-cash expense and income | F22: Annual statement | G22: =IF(M22="","",IF(AND(M22>=-1,M22<=1), "%","mln EUR")) -> mln EUR | J22: -11503 | K22: -1296 | L22: -2369 | M22: -1362 | N22: -1204
D23: Gains (-)/losses (+) from disposals of non-current assets | F23: Annual statement | G23: =IF(M23="","",IF(AND(M23>=-1,M23<=1), "%","mln EUR")) -> mln EUR | J23: -695 | K23: -990 | L23: -92 | M23: 18 | N23: 65
G24: =IF(M24="","",IF(AND(M24>=-1,M24<=1), "%","mln EUR"))
C25: Change in operating assets and liabilities
G26: =IF(M26="","",IF(AND(M26>=-1,M26<=1), "%","mln EUR"))
D27: Inventories | F27: Annual statement | G27: =IF(M27="","",IF(AND(M27>=-1,M27<=1), "%","mln EUR")) -> mln EUR | J27: -2561 | K27: -4111 | L27: -2420 | M27: 737 | N27: 724
D28: Trade receivables and trade liabilities | F28: Annual statement | G28: =IF(M28="","",IF(AND(M28>=-1,M28<=1), "%","mln EUR")) -> mln EUR | J28: 1694 | K28: 1029 | L28: 1310 | M28: -1199 | N28: 895
D29: Receivables from financial services | F29: Annual statement | G29: =IF(M29="","",IF(AND(M29>=-1,M29<=1), "%","mln EUR")) -> mln EUR | J29: 3879 | K29: -5327 | L29: -6125 | M29: 3280 | N29: 5828
D30: Vehicles on operating leases | F30: Annual statement | G30: =IF(M30="","",IF(AND(M30>=-1,M30<=1), "%","mln EUR")) -> mln EUR | J30: 1428 | K30: 3810 | L30: -640 | M30: -3110 | N30: -4060
D31: Other operating assets and liabilities | F31: Annual statement | G31: =IF(M31="","",IF(AND(M31>=-1,M31<=1), "%","mln EUR")) -> mln EUR | J31: -1261 | K31: 358 | L31: 1624 | M31: 986 | N31: 2585
G32: =IF(M32="","",IF(AND(M32>=-1,M32<=1), "%","mln EUR"))
D33: Dividends received from equity-method investments | F33: Annual statement | G33: =IF(M33="","",IF(AND(M33>=-1,M33<=1), "%","mln EUR")) -> mln EUR | J33: 1625 | K33: 1605 | L33: 2056 | M33: 1918 | N33: 1330
D34: Income taxes paid | F34: Annual statement | G34: =IF(M34="","",IF(AND(M34>=-1,M34<=1), "%","mln EUR")) -> mln EUR | J34: -3812 | K34: -5009 | L34: -5621 | M34: -4452 | N34: -1664
G35: =IF(M35="","",IF(AND(M35>=-1,M35<=1), "%","mln EUR"))
C36: Total cashflow from operating activities
G37: =IF(M37="","",IF(AND(M37>=-1,M37<=1), "%","mln EUR"))
D38: Total cashflow from operating activities | F38: Annual statement | G38: =IF(M38="","",IF(AND(M38>=-1,M38<=1), "%","mln EUR")) -> mln EUR | J38: 24549 | K38: 16894 | L38: 14470 | M38: 17735 | N38: 18006
G39: =IF(M39="","",IF(AND(M39>=-1,M39<=1), "%","mln EUR"))
B40: Cashflow from investing activities
C42: Cashflow from investing activities
G43: =IF(M43="","",IF(AND(M43>=-1,M43<=1), "%","mln EUR"))
D44: Additions to property, plant and equipment | F44: Annual statement | G44: =IF(M44="","",IF(AND(M44>=-1,M44<=1), "%","mln EUR")) -> mln EUR | J44: -4579 | K44: -3481 | L44: -3745 | M44: -4039 | N44: -5482
D45: Additions to intangible assets | F45: Annual statement | G45: =IF(M45="","",IF(AND(M45>=-1,M45<=1), "%","mln EUR")) -> mln EUR | J45: -2741 | K45: -3418 | L45: -4468 | M45: -4626 | N45: -4260
D46: Investments in shareholdings | F46: Annual statement | G46: =IF(M46="","",IF(AND(M46>=-1,M46<=1), "%","mln EUR")) -> mln EUR | J46: -573 | K46: -849 | L46: -334 | M46: -363 | N46: -304
D47: Cash inflows from disposals of shareholdings and other business operations | F47: Annual statement | G47: =IF(M47="","",IF(AND(M47>=-1,M47<=1), "%","mln EUR")) -> mln EUR | J47: 793 | K47: 3337 | L47: 612 | M47: 716 | N47: 413
D48: Acquisition of marketable debt securities and similar investments | F48: Annual statement | G48: =IF(M48="","",IF(AND(M48>=-1,M48<=1), "%","mln EUR")) -> mln EUR | J48: -5694 | K48: -2622 | L48: -4714 | M48: -6785 | N48: -12303
...

Sheet 2. Calcs

Sheet EBITDA
A5: EBITDA | F5: Source | G5: UoM | I5: Const | J5: 2021A | K5: 2022A | L5: 2023A | M5: 2024A | N5: 2025A
D8: EBIT (from the IS) | F8: Link | G8: =IF(M8="","",IF(AND(M8>=-1,M8<=1), "%","mln EUR")) -> mln EUR | J8: =PL!J39 -> 16028 | K8: =PL!K39 -> 20458 | L8: =PL!L39 -> 19660 | M8: =PL!M39 -> 13599 | N8: =PL!N39 -> 5820
D9: + Depreciation & Amortization | F9: AS Note 34 | G9: =IF(M9="","",IF(AND(M9>=-1,M9<=1), "%","mln EUR")) -> mln EUR | J9: 15066 | K9: 13891 | L9: 13697 | M9: 14680 | N9: =15121 -> 15121
G10: =IF(M10="","",IF(AND(M10>=-1,M10<=1), "%","mln EUR"))
D11: Non-operating items | G11: =IF(M11="","",IF(AND(M11>=-1,M11<=1), "%","mln EUR"))
G12: =IF(M12="","",IF(AND(M12>=-1,M12<=1), "%","mln EUR"))
D13: (-)Other operating income | F13: AS Note 6 | G13: =IF(M13="","",IF(AND(M13>=-1,M13<=1), "%","mln EUR")) -> mln EUR | J13: -2888 | K13: -3323 | L13: -2206 | M13: -2507 | N13: =-1551 -> -1551
D14: (+)Other operating expense | F14: AS Note 6 | G14: =IF(M14="","",IF(AND(M14>=-1,M14<=1), "%","mln EUR")) -> mln EUR | J14: 1735 | K14: 1289 | L14: 516 | M14: 483 | N14: =1025 -> 1025
D15: (-)Other financial income/expenses | F15: AS Note 7 | G15: =IF(M15="","",IF(AND(M15>=-1,M15<=1), "%","mln EUR")) -> mln EUR | J15: -317 | K15: -340 | L15: -108 | M15: 37 | N15: =-93 -> -93
D16: (-)Gains and losses on equity-method investments | F16: AS Note 13 | G16: =IF(M16="","",IF(AND(M16>=-1,M16<=1), "%","mln EUR")) -> mln EUR | J16: -1352 | K16: -1732 | L16: -2129 | M16: -1138 | N16: =-1118 -> -1118
D18: EBITDA | F18: Calcs | J18: =J8+J9+J13+J14+J15+J16 -> 28272 | K18: =K8+K9+K13+K14+K15+K16 -> 30243 | L18: =L8+L9+L13+L14+L15+L16 -> 29430 | M18: =M8+M9+M13+M14+M15+M16 -> 25154 | N18: =N8+N9+N13+N14+N15+N16 -> 19204
C20: Net Profit
D22: Net Profit | F22: Link | G22: =IF(M22="","",IF(AND(M22>=-1,M22<=1), "%","mln EUR")) -> mln EUR | J22: =PL!J52 -> 23396 | K22: =PL!K52 -> 14809 | L22: =PL!L52 -> 14531 | M22: =PL!M52 -> 10409 | N22: =PL!N52 -> 5331
D23: Revenue | F23: Link | G23: =IF(M23="","",IF(AND(M23>=-1,M23<=1), "%","mln EUR")) -> mln EUR | J23: =PL!J11 -> 133893 | K23: =PL!K11 -> 150017 | L23: =PL!L11 -> 152390 | M23: =PL!M11 -> 145594 | N23: =PL!N11 -> 132214
C25: Margins
D27: EBITDA margin | F27: Calcs | G27: =IF(M27="","",IF(AND(M27>=-1,M27<=1), "%","mln EUR")) -> % | J27: =J18/J23 -> 0.21115368 | K27: =K18/K23 -> 0.20159715 | L27: =L18/L23 -> 0.19312291 | M27: =M18/M23 -> 0.17276811 | N27: =N18/N23 -> 0.14524937
D28: EBIT margin | F28: Link | G28: =IF(M28="","",IF(AND(M28>=-1,M28<=1), "%","mln EUR")) -> % | J28: =J8/J23 -> 0.11970753 | K28: =K8/K23 -> 0.13637121 | L28: =L8/L23 -> 0.12901109 | M28: =M8/M23 -> 0.093403574 | N28: =N8/N23 -> 0.044019544

Sheet Ratios
C1: Variable | D1: Value | E1: Source
C3: Current share price as of 29 May 2026 in EUR | D3: 52.19 | E3: https://finance.yahoo.com/quote/MBG.DE
C4: Number of shares issued as of 30 September 2025 in mln EUR | D4: =962903703/1000000 -> 962.9037 | E4: https://group.mercedes-benz.com/investors/share/
C5: Cash and cash equivalents | D5: =BS!N57 -> 12254 | E5: Annual statement
C6: Total Debt (LT Debt + ST Debt + Lease) in mln EUR | D6: =BS!N95+BS!N129+888 -> 100894 | E6: AS Note 24
C7: Net Debt (Total Debt - Cash & Cash Equivalents in mln EUR | D7: =D6-BS!N57 -> 88640 | E7: Annual statement

Sheet 3. Comps

Sheet BMW
A1: Link: https://www.bmwgroup.com/content/dam/grpw/websites/bmwgroup_com/ir/downloads/en/2026/bericht/BMW-Group-Report-2025-en.pdf
E3: Source | F3: UoM | H3: Const | I3: 2025A
B4: Income statement (P&L) | F4: Source | G4: UoM | I4: 2025A
B5: PAGE 271
D6: Revenue | F6: Annual statement | G6: mln EUR | I6: 133453
G7: =IF(I7="","",IF(AND(I7>=-1,I7<=1), "%","mln EUR"))
D8: Cost of goods sold | F8: Annual statement | G8: =IF(I8="","",IF(AND(I8>=-1,I8<=1), "%","mln EUR")) -> mln EUR | I8: =-112858 -> -112858
G9: =IF(I9="","",IF(AND(I9>=-1,I9<=1), "%","mln EUR"))
D10: Gross profit | F10: Annual statement | G10: =IF(I10="","",IF(AND(I10>=-1,I10<=1), "%","mln EUR")) -> mln EUR | I10: =I8+I6 -> 20595
G11: =IF(I11="","",IF(AND(I11>=-1,I11<=1), "%","mln EUR"))
D12: SGA | F12: Annual statement | G12: =IF(I12="","",IF(AND(I12>=-1,I12<=1), "%","mln EUR")) -> mln EUR | I12: =-10606 -> -10606
G13: =IF(I13="","",IF(AND(I13>=-1,I13<=1), "%","mln EUR"))
D14: Other operating income/expense | F14: Annual statement | G14: mln EUR | I14: =1556-1359 -> 197
G15: =IF(I15="","",IF(AND(I15>=-1,I15<=1), "%","mln EUR"))
D16: Gains/losses on equity-method invesments, net | F16: Annual statement | G16: =IF(I16="","",IF(AND(I16>=-1,I16<=1), "%","mln EUR")) -> mln EUR | I16: 38
G17: =IF(I17="","",IF(AND(I17>=-1,I17<=1), "%","mln EUR"))
D18: Other financial income/expense, net | F18: Annual statement | G18: =IF(I18="","",IF(AND(I18>=-1,I18<=1), "%","mln EUR")) -> mln EUR | I18: 72
G19: =IF(I19="","",IF(AND(I19>=-1,I19<=1), "%","mln EUR"))
D20: EBIT | F20: Annual statement | G20: =IF(I20="","",IF(AND(I20>=-1,I20<=1), "%","mln EUR")) -> mln EUR | I20: =I10+I12+I14+I16+I18 -> 10296
G21: =IF(I21="","",IF(AND(I21>=-1,I21<=1), "%","mln EUR"))
D22: Interest income | F22: Annual statement | G22: =IF(I22="","",IF(AND(I22>=-1,I22<=1), "%","mln EUR")) -> mln EUR | I22: =502-562 -> -60
G23: =IF(I23="","",IF(AND(I23>=-1,I23<=1), "%","mln EUR"))
D24: Profit before income taxes | F24: Annual statement | G24: =IF(I24="","",IF(AND(I24>=-1,I24<=1), "%","mln EUR")) -> mln EUR | I24: =10236 -> 10236
G25: =IF(I25="","",IF(AND(I25>=-1,I25<=1), "%","mln EUR"))
D26: Income taxes | F26: Annual statement | G26: =IF(I26="","",IF(AND(I26>=-1,I26<=1), "%","mln EUR")) -> mln EUR | I26: =-2785 -> -2785
G27: =IF(I27="","",IF(AND(I27>=-1,I27<=1), "%","mln EUR"))
D28: Net profit | F28: Annual statement | G28: =IF(I28="","",IF(AND(I28>=-1,I28<=1), "%","mln EUR")) -> mln EUR | I28: =7451 -> 7451
C31: EBITDA
D33: EBIT (from the IS) | F33: Link | G33: =IF(M33="","",IF(AND(M33>=-1,M33<=1), "%","mln EUR")) | I33: =I20 -> 10296
D34: + Depreciation & Amortization | F34: AS Note 46, page 349 | G34: =IF(M34="","",IF(AND(M34>=-1,M34<=1), "%","mln EUR")) | I34: 15219
G35: =IF(M35="","",IF(AND(M35>=-1,M35<=1), "%","mln EUR"))
D36: Non-operating items | G36: =IF(M36="","",IF(AND(M36>=-1,M36<=1), "%","mln EUR"))
G37: =IF(M37="","",IF(AND(M37>=-1,M37<=1), "%","mln EUR"))
D38: (-)Other operating income | F38: Page 271 | G38: =IF(M38="","",IF(AND(M38>=-1,M38<=1), "%","mln EUR")) | I38: -1556
D39: (+)Other operating expense | F39: Page 271 | G39: =IF(M39="","",IF(AND(M39>=-1,M39<=1), "%","mln EUR")) | I39: 1359
D40: (-)Other financial income/expenses | F40: AS Note 7 | G40: =IF(M40="","",IF(AND(M40>=-1,M40<=1), "%","mln EUR")) | I40: =-I18 -> -72
D41: (-)Gains and losses on equity-method investments | F41: AS Note 13 | G41: =IF(M41="","",IF(AND(M41>=-1,M41<=1), "%","mln EUR")) | I41: =-I16 -> -38
D43: EBITDA | F43: Calcs | I43: =I33+I34+I38+I39+I40+I41 -> 25208
C45: Net Profit
D47: Net Profit | F47: Link | G47: =IF(M47="","",IF(AND(M47>=-1,M47<=1), "%","mln EUR")) | I47: =I28 -> 7451
...

Sheet VW
A1: Link: https://uploads.vw-mms.de/system/production/documents/cws/003/212/file_en/41966a4270c8a0a4185b3ab69eaa433cf6892168/annual-report-2025-volkswagen-group.pdf?1773224256
A2: https://finance.yahoo.com/quote/VOW3.DE/history/
E3: Source | F3: UoM | H3: Const | I3: 2025A
B4: Income statement (P&L) | F4: Source | G4: UoM | I4: 2025A
D6: Revenue | F6: Annual statement | G6: mln EUR | I6: 321913
G7: =IF(I7="","",IF(AND(I7>=-1,I7<=1), "%","mln EUR"))
D8: Cost of goods sold | F8: Annual statement | G8: =IF(I8="","",IF(AND(I8>=-1,I8<=1), "%","mln EUR")) -> mln EUR | I8: -270671
G9: =IF(I9="","",IF(AND(I9>=-1,I9<=1), "%","mln EUR"))
D10: Gross profit | F10: Annual statement | G10: =IF(I10="","",IF(AND(I10>=-1,I10<=1), "%","mln EUR")) -> mln EUR | I10: =I6+I8 -> 51242
G11: =IF(I11="","",IF(AND(I11>=-1,I11<=1), "%","mln EUR"))
D12: SGA | F12: Annual statement | G12: =IF(I12="","",IF(AND(I12>=-1,I12<=1), "%","mln EUR")) -> mln EUR | I12: =-22804-12541 -> -35345
G13: =IF(I13="","",IF(AND(I13>=-1,I13<=1), "%","mln EUR"))
D14: Other operating income/expense | F14: Annual statement | G14: mln EUR | I14: =-7029 -> -7029
G15: =IF(I15="","",IF(AND(I15>=-1,I15<=1), "%","mln EUR"))
D16: Gains/losses on equity-method invesments, net | F16: Annual statement, Note 7, page 503 | G16: =IF(I16="","",IF(AND(I16>=-1,I16<=1), "%","mln EUR")) -> mln EUR | I16: 930
G17: =IF(I17="","",IF(AND(I17>=-1,I17<=1), "%","mln EUR"))
D18: Other financial income/expense, net | F18: Annual statement, Note 9, page 504 | G18: =IF(I18="","",IF(AND(I18>=-1,I18<=1), "%","mln EUR")) -> mln EUR | I18: 930
G19: =IF(I19="","",IF(AND(I19>=-1,I19<=1), "%","mln EUR"))
D20: EBIT | F20: Annual statement | G20: =IF(I20="","",IF(AND(I20>=-1,I20<=1), "%","mln EUR")) -> mln EUR | I20: =I10+I12+I14+I16+I18 -> 10728
G21: =IF(I21="","",IF(AND(I21>=-1,I21<=1), "%","mln EUR"))
D22: Interest income | F22: Annual statement, Note 8, page 504 | G22: =IF(I22="","",IF(AND(I22>=-1,I22<=1), "%","mln EUR")) -> mln EUR | I22: 1824
G23: =IF(I23="","",IF(AND(I23>=-1,I23<=1), "%","mln EUR"))
D24: Profit before income taxes | F24: Annual statement | G24: =IF(I24="","",IF(AND(I24>=-1,I24<=1), "%","mln EUR")) -> mln EUR | I24: =I20+I22 -> 12552
G25: =IF(I25="","",IF(AND(I25>=-1,I25<=1), "%","mln EUR"))
D26: Income taxes | F26: Annual statement | G26: =IF(I26="","",IF(AND(I26>=-1,I26<=1), "%","mln EUR")) -> mln EUR | I26: -2403
G27: =IF(I27="","",IF(AND(I27>=-1,I27<=1), "%","mln EUR"))
D28: Net profit | F28: Annual statement | G28: =IF(I28="","",IF(AND(I28>=-1,I28<=1), "%","mln EUR")) -> mln EUR | I28: =I24+I26 -> 10149
C31: EBITDA
D33: EBIT (from the IS) | F33: Link | G33: =IF(M33="","",IF(AND(M33>=-1,M33<=1), "%","mln EUR")) | I33: =I20 -> 10728
D34: + Depreciation & Amortization | F34: Annual statement, CF | G34: =IF(M34="","",IF(AND(M34>=-1,M34<=1), "%","mln EUR")) | I34: =16866+8365 -> 25231
G35: =IF(M35="","",IF(AND(M35>=-1,M35<=1), "%","mln EUR"))
D36: Non-operating items | G36: =IF(M36="","",IF(AND(M36>=-1,M36<=1), "%","mln EUR"))
G37: =IF(M37="","",IF(AND(M37>=-1,M37<=1), "%","mln EUR"))
D38: (-)Other operating income | F38: Annual statement | G38: =IF(M38="","",IF(AND(M38>=-1,M38<=1), "%","mln EUR"))
D39: (+)Other operating expense | F39: Annual statement | G39: =IF(M39="","",IF(AND(M39>=-1,M39<=1), "%","mln EUR")) | I39: =-I14 -> 7029
D40: (-)Other financial income/expenses | F40: Annual statement | G40: =IF(M40="","",IF(AND(M40>=-1,M40<=1), "%","mln EUR")) | I40: =-I18 -> -930
D41: (-)Gains and losses on equity-method investments | F41: Annual statement | G41: =IF(M41="","",IF(AND(M41>=-1,M41<=1), "%","mln EUR")) | I41: =-I16 -> -930
D43: EBITDA | F43: Calcs | I43: =I33+I34+I38+I39+I40+I41 -> 41128
C45: Net Profit
D47: Net Profit | F47: Link | G47: =IF(M47="","",IF(AND(M47>=-1,M47<=1), "%","mln EUR")) | I47: =I28 -> 10149
...

Sheet Porsche
A1: Link: https://newsroom.porsche.com/en/annual-sustainability-report/consolidated-financial-statements/consolidated-income-statement/
A2: https://newsroom.porsche.com/assets/uploads/documents/Notes_to_the_consolidated_financial_statements_2025_Porsche_AG.pdf
E3: Source | F3: UoM | H3: Const | I3: 2025A
B4: Income statement (P&L) | F4: Source | G4: UoM | I4: 2025A
D6: Revenue | F6: Annual statement | G6: mln EUR | I6: 36272
G7: =IF(I7="","",IF(AND(I7>=-1,I7<=1), "%","mln EUR"))
D8: Cost of goods sold | F8: Annual statement | G8: =IF(I8="","",IF(AND(I8>=-1,I8<=1), "%","mln EUR")) -> mln EUR | I8: -31221
G9: =IF(I9="","",IF(AND(I9>=-1,I9<=1), "%","mln EUR"))
D10: Gross profit | F10: Annual statement | G10: =IF(I10="","",IF(AND(I10>=-1,I10<=1), "%","mln EUR")) -> mln EUR | I10: =I6+I8 -> 5051
G11: =IF(I11="","",IF(AND(I11>=-1,I11<=1), "%","mln EUR"))
D12: SGA | F12: Annual statement | G12: =IF(I12="","",IF(AND(I12>=-1,I12<=1), "%","mln EUR")) -> mln EUR | I12: -4694
G13: =IF(I13="","",IF(AND(I13>=-1,I13<=1), "%","mln EUR"))
D14: Other operating income/expense | F14: Annual statement | G14: mln EUR | I14: =1460-1403 -> 57
G15: =IF(I15="","",IF(AND(I15>=-1,I15<=1), "%","mln EUR"))
D16: Gains/losses on equity-method invesments, net | F16: Annual statement | G16: =IF(I16="","",IF(AND(I16>=-1,I16<=1), "%","mln EUR")) -> mln EUR | I16: -35
G17: =IF(I17="","",IF(AND(I17>=-1,I17<=1), "%","mln EUR"))
D18: Other financial income/expense, net | F18: Annual statement | G18: =IF(I18="","",IF(AND(I18>=-1,I18<=1), "%","mln EUR")) -> mln EUR | I18: =47 -> 47
G19: =IF(I19="","",IF(AND(I19>=-1,I19<=1), "%","mln EUR"))
D20: EBIT | F20: Annual statement | G20: =IF(I20="","",IF(AND(I20>=-1,I20<=1), "%","mln EUR")) -> mln EUR | I20: =I10+I12+I14+I16+I18 -> 426
G21: =IF(I21="","",IF(AND(I21>=-1,I21<=1), "%","mln EUR"))
D22: Interest income | F22: Annual statement | G22: =IF(I22="","",IF(AND(I22>=-1,I22<=1), "%","mln EUR")) -> mln EUR | I22: =188-169 -> 19
G23: =IF(I23="","",IF(AND(I23>=-1,I23<=1), "%","mln EUR"))
D24: Profit before income taxes | F24: Annual statement | G24: =IF(I24="","",IF(AND(I24>=-1,I24<=1), "%","mln EUR")) -> mln EUR | I24: =I20+I22 -> 445
G25: =IF(I25="","",IF(AND(I25>=-1,I25<=1), "%","mln EUR"))
D26: Income taxes | F26: Annual statement | G26: =IF(I26="","",IF(AND(I26>=-1,I26<=1), "%","mln EUR")) -> mln EUR | I26: -135
G27: =IF(I27="","",IF(AND(I27>=-1,I27<=1), "%","mln EUR"))
D28: Net profit | F28: Annual statement | G28: =IF(I28="","",IF(AND(I28>=-1,I28<=1), "%","mln EUR")) -> mln EUR | I28: =I24+I26 -> 310
C31: EBITDA
D33: EBIT (from the IS) | F33: Link | G33: =IF(M33="","",IF(AND(M33>=-1,M33<=1), "%","mln EUR")) | I33: =I20 -> 426
D34: + Depreciation & Amortization | F34: AS Note, page 351 (25) | G34: =IF(M34="","",IF(AND(M34>=-1,M34<=1), "%","mln EUR")) | I34: 3984
G35: =IF(M35="","",IF(AND(M35>=-1,M35<=1), "%","mln EUR"))
D36: Non-operating items | G36: =IF(M36="","",IF(AND(M36>=-1,M36<=1), "%","mln EUR"))
G37: =IF(M37="","",IF(AND(M37>=-1,M37<=1), "%","mln EUR"))
D38: (-)Other operating income | F38: Annual statement | G38: =IF(M38="","",IF(AND(M38>=-1,M38<=1), "%","mln EUR")) | I38: -1460
D39: (+)Other operating expense | F39: Annual statement | G39: =IF(M39="","",IF(AND(M39>=-1,M39<=1), "%","mln EUR")) | I39: 1403
D40: (-)Other financial income/expenses | F40: Annual statement | G40: =IF(M40="","",IF(AND(M40>=-1,M40<=1), "%","mln EUR")) | I40: =-I18 -> -47
D41: (-)Gains and losses on equity-method investments | F41: Annual statement | G41: =IF(M41="","",IF(AND(M41>=-1,M41<=1), "%","mln EUR")) | I41: =-I16 -> 35
D43: EBITDA | F43: Calcs | I43: =I33+I34+I38+I39+I40+I41 -> 4341
C45: Net Profit
D47: Net Profit | F47: Link | G47: =IF(M47="","",IF(AND(M47>=-1,M47<=1), "%","mln EUR")) | I47: =I28 -> 310
...

Sheet Relative Valuation
B2: Relative Valuation
C4: As of 21.05.2026
C6: Peer | D6: EPS, € | E6: Share Price, € | F6: P/E | G6: Weight
C7: BMW | D7: =BMW!I124 -> 11.89 | E7: =BMW!I102 -> 74.11 | F7: =E7/D7 -> 6.2329689 | G7: =0.6 -> 0.6
C8: VW | D8: =VW!I122 -> 13.29 | E8: =VW!I102 -> 88.5 | F8: =E8/D8 -> 6.6591422 | G8: =0.35 -> 0.35
C9: Porsche | D9: =Porsche!I124 -> 0.48 | E9: =Porsche!I102 -> 45.35 | F9: =E9/D9 -> 94.479167 | G9: =1-G7-G8 -> 0.05
C10: Weighted | F10: =SUMPRODUCT(F7:F9,G7:G9) -> 10.794439
C12: Peer | D12: EV, mln € | E12: EBITDA, mln € | F12: EV/EBITDA | G12: Weight
C13: BMW | D13: =BMW!I116/1000000 -> 139306.39 | E13: =BMW!I43 -> 25208 | F13: =D13/E13 -> 5.526277 | G13: =0.5 -> 0.5
C14: VW | D14: =VW!I114/1000000 -> 285043.63 | E14: =VW!I43 -> 41128 | F14: =D14/E14 -> 6.9306465 | G14: =0.3 -> 0.3
C15: Porsche | D15: =Porsche!I114/1000000 -> 47878.85 | E15: =Porsche!I43 -> 4341 | F15: =D15/E15 -> 11.029452 | G15: =1-G13-G14 -> 0.2
C16: Weighted | F16: =SUMPRODUCT(F13:F15,G13:G15) -> 7.0482228
C18: As of 21.05.26 | D18: Earnings per share, € | E18: Implied Share Price, € | F18: EBITDA, mln € | G18: Implied EV, mln € | H18: Implied Equity Value, mln € | I18: Number of Shares Outstanding | J18: Implied Share Price, €
C19: Mercedes | D19: =PL!N65 -> 5.34 | E19: =D19*F10 -> 57.642307 | F19: =EBITDA!N18 -> 19204 | G19: =F19*F16 -> 135354.07 | H19: =G19-BS!N95-BS!N129+BS!N57-BS!N186 -> 46596.07 | I19: 962903703 | J19: =H19*1000000/I19 -> 48.391205
C22: As of 21.05.26 | D22: Implied Share Price, €
C23: Mercedes | D23: =0.7*J19+0.3*E19 -> 51.166535
C27: Real price | E27: =49.76 -> 49.76
C28: https://ru.investing.com/equities/daimler

Sheet 4. DCF

Sheet Beta
D1: Mercedes | F1: DAX 40 | K1: Sources
K2: Mercedes | L2: Adj Close | M2: https://finance.yahoo.com/quote/MBG.DE/history/?frequency=1mo&period1=846662400&period2=1779099298
C3: Date | D3: Price, EUR | E3: Return, % | F3: Price, EUR | G3: Return, % | K3: DAX 40 | L3: Adj Close | M3: https://finance.yahoo.com/quote/%5EGDAXI/history/?frequency=1mo&period1=567849600&period2=1779099298
C5: 46173 | D5: 50.349998 | E5: =D5/D6-1 -> 0.015428041 | F5: 23950.57 | G5: =F5/F6-1 -> -0.014070689 | K5: Observations
C6: 46142 | D6: 49.584999 | E6: =D6/D7-1 -> 0.012910737 | F6: 24292.381 | G6: =F6/F7-1 -> 0.071090786 | K6: n | L6: 120
C7: 46112 | D7: 48.95298 | E7: =D7/D8-1 -> -0.11203389 | F7: 22680.039 | G7: =F7/F8-1 -> -0.1029977 | K7: range | L7: 42400 | M7: 46022
C8: 46081 | D8: 55.129333 | E8: =D8/D9-1 -> 0.020937888 | F8: 25284.26 | G8: =F8/F9-1 -> 0.030378376
C9: 46053 | D9: 53.998714 | E9: =D9/D10-1 -> -0.037955701 | F9: 24538.811 | G9: =F9/F10-1 -> 0.0019762997 | K9: Calculation
C10: 46022 | D10: 56.129135 | E10: =D10/D11-1 -> 0.032840428 | F10: 24490.41 | G10: =F10/F11-1 -> 0.027420685 | K10: DAX Std | L10: =_xlfn.STDEV.S(G10:G129) -> 0.046804063
C11: 45991 | D11: 54.34444 | E11: =D11/D12-1 -> 0.034691334 | F11: 23836.789 | G11: =F11/F12-1 -> -0.0050718004 | K11: DAX Var | L11: =_xlfn.VAR.S(G10:G129) -> 0.0021906203
C12: 45961 | D12: 52.522369 | E12: =D12/D13-1 -> 0.04305065 | F12: 23958.301 | G12: =F12/F13-1 -> 0.0032486489 | K12: CoVar | L12: =_xlfn.COVARIANCE.S(G10:G129,E10:E129) -> 0.0029481961
C13: 45930 | D13: 50.354572 | E13: =D13/D14-1 -> 0.010121842 | F13: 23880.721 | G13: =F13/F14-1 -> -0.00089908981 | K13: Beta | L13: =L12/L11 -> 1.3458271 | M13: Unadjusted Beta is preferred over adjusted in further analysis to reflect company and market instability and industry EV disruption
C14: 45900 | D14: 49.849998 | E14: =D14/D15-1 -> 0.064870256 | F14: 23902.211 | G14: =F14/F15-1 -> -0.0067839839 | K14: Adj. Beta | L14: =L13*2/3+1/3 -> 1.2305514
C15: 45869 | D15: 46.813213 | E15: =D15/D16-1 -> 0.0082511631 | F15: 24065.471 | G15: =F15/F16-1 -> 0.0065187735
C16: 45838 | D16: 46.430111 | E16: =D16/D17-1 -> -0.055143572 | F16: 23909.609 | G16: =F16/F17-1 -> -0.00366168
C17: 45808 | D17: 49.139858 | E17: =D17/D18-1 -> 0.089021457 | F17: 23997.48 | G17: =F17/F18-1 -> 0.06669784
C18: 45777 | D18: 45.122948 | E18: =D18/D19-1 -> -0.031740202 | F18: 22496.98 | G18: =F18/F19-1 -> 0.015046828
C19: 45747 | D19: 46.602108 | E19: =D19/D20-1 -> -0.093357889 | F19: 22163.49 | G19: =F19/F20-1 -> -0.017202433
C20: 45716 | D20: 51.400776 | E20: =D20/D21-1 -> 0.014426421 | F20: 22551.43 | G20: =F20/F21-1 -> 0.037703708
C21: 45688 | D21: 50.669792 | E21: =D21/D22-1 -> 0.095167251 | F21: 21732.051 | G21: =F21/F22-1 -> 0.091561469
C22: 45657 | D22: 46.266716 | E22: =D22/D23-1 -> 0.015861064 | F22: 19909.141 | G22: =F22/F23-1 -> 0.014403594
C23: 45626 | D23: 45.544334 | E23: =D23/D24-1 -> -0.04919218 | F23: 19626.449 | G23: =F23/F24-1 -> 0.028772587
C24: 45596 | D24: 47.900673 | E24: =D24/D25-1 -> -0.040317025 | F24: 19077.539 | G24: =F24/F25-1 -> -0.012801631
C25: 45565 | D25: 49.913017 | E25: =D25/D26-1 -> -0.068976536 | F25: 19324.93 | G25: =F25/F26-1 -> 0.022108824
C26: 45535 | D26: 53.610912 | E26: =D26/D27-1 -> 0.01929363 | F26: 18906.92 | G26: =F26/F27-1 -> 0.021518021
... C359: 35399 | D359: 10.546446 | E359: =D359/D360-1 -> 0.12650812 | F359: 2848.8401 | G359: =F359/F360-1 -> 0.066422173
C360: 35369 | D360: 9.3620682 | E360: =D360/#REF!-1 -> #REF! | F360: 2671.3999 | G360: =F360/#REF!-1 -> #REF!

Sheet COE
H1: Rf | I1: 0.0315 | J1: (Germany 10Y Bonds)
H2: US 10Y Bonds | I2: 0.04656
H3: Default spread | I3: 0
H4: Inflation premium | I4: =((1+I5)/(1+I6))-1 -> 0 | K4: =I2+I3+I4 -> 0.04656
H5: Ger Inflation | I5: 0.02
H6: US Inflation target | I6: 0.02
H7: Beta | I7: =Beta!L13 -> 1.3458271 | J7: Illia's calculation | R7: https://curvo.eu/backtest/en/compare-indexes/cac-40-vs-dax?currency=eur
H8: Rm | I8: 0.086 | J8: DAX 40 avr last 10y return
H10: COE | I10: =I1+I7*(I8-I1) -> 0.10484757

Sheet COD
A1: Based on credit rating: | E1: Rf | F1: =COE!$I$1 -> 0.0315
E2: Credit Spread | F2: 0.0072
A3: S&P Rating | B3: A
A6: Rd = Rf + Credit spread | E6: COD | F6: =F1+F2 -> 0.0387
R16: https://pages.stern.nyu.edu/~adamodar/New_Home_Page/datafile/ctryprem.html

Sheet WACC
H1: Equity | I1: =BS!N191 -> 94263 | J1: mln. EUR
H2: Debt | I2: =BS!N95+BS!N129 -> 100006 | J2: mln. EUR
H3: D+E | I3: =SUM(I1:I2) -> 194269 | J3: mln. EUR
H4: COE | I4: =COE!I10 -> 0.10484757
H5: COD | I5: =COD!F6 -> 0.0387
H6: EBT | I6: 6248 | J6: mln. EUR | K6: from PnL
H7: T in EUR | I7: 953 | J7: mln. EUR
H8: T in % | I8: =I7/I6 -> 0.15252881
H9: Inncome tax | I9: 0.3
H11: WACC | I11: =((I1/I3)*I4)+((I2/I3)*I5*(1-I9)) -> 0.064819449

Sheet DCF
C1: Free Cash Flow to the Firm Model
C3: in mln of euros | D3: Source | E3: Comment | F3: 2021 | G3: =F3+1 -> 2022 | H3: =G3+1 -> 2023 | I3: =H3+1 -> 2024 | J3: 2025 | K3: =J3+1 -> 2026 | L3: =K3+1 -> 2027 | M3: =L3+1 -> 2028 | N3: =M3+1 -> 2029 | O3: =N3+1 -> 2030 | P3: =O3+1 -> 2031 | Q3: =P3+1 -> 2032 | R3: =Q3+1 -> 2033 | ... T3: =S3+1 -> 2035
C5: Revenue | D5: Link | F5: =PL!J11 -> 133893 | G5: =PL!K11 -> 150017 | H5: =PL!L11 -> 152390 | I5: =PL!M11 -> 145594 | J5: =PL!N11 -> 132214 | K5: =J5*(1+K6) -> 125735.51 | L5: =K5*(1+L6) -> 122592.13 | M5: =L5*(1+M6) -> 121979.17 | N5: =M5*(1+N6) -> 121979.17 | O5: =N5*(1+O6) -> 122101.14 | P5: =O5*(1+P6) -> 122345.35 | Q5: =P5*(1+Q6) -> 122712.38 | R5: =Q5*(1+R6) -> 123203.23 | ... T5: =S5*(1+T6) -> 124438.34
C6: Growth, % | D6: Calcs | E6: 2025 saw US tariffs and a 29% decline in China following another 27% decline in deliveries in 2026Q1 due to strong competition, the trend likely to continue in the following year. The company, however, is making progress in the EV sector with the success of the new Mercedes-Benz CLA, MB.OS and VAN.EA in 2026. | G6: =G5/F5-1 -> 0.12042452 | H6: =H5/G5-1 -> 0.015818207 | I6: =I5/H5-1 -> -0.044596102 | J6: =J5/I5-1 -> -0.091899391 | K6: =-4.9% -> -0.049 | L6: -0.025 | M6: -0.005 | N6: 0 | O6: 0.001 | P6: 0.002 | Q6: 0.003 | R6: 0.004 | S6: 0.005 | T6: 0.005
C8: EBITDA | D8: Link | F8: =EBITDA!J18 -> 28272 | G8: =EBITDA!K18 -> 30243 | H8: =EBITDA!L18 -> 29430 | I8: =EBITDA!M18 -> 25154 | J8: =EBITDA!N18 -> 19204 | K8: =K5*K9 -> 18860.327 | L8: =L5*L9 -> 18388.819 | M8: =M5*M9 -> 19516.666 | N8: =N5*N9 -> 19516.666 | O8: =O5*O9 -> 19536.183 | P8: =P5*P9 -> 19575.256 | Q8: =Q5*Q9 -> 20861.105 | R8: =R5*R9 -> 20944.55 | ... T8: =T5*T9 -> 21154.519
C9: EBITDA margin, % | D9: Calcs | E9: EBITDA margin took a hit due to tariffs and China headwinds, but is expected to gradually stabilise. | F9: =F8/F5 -> 0.21115368 | G9: =G8/G5 -> 0.20159715 | H9: =H8/H5 -> 0.19312291 | I9: =I8/I5 -> 0.17276811 | J9: =J8/J5 -> 0.14524937 | K9: 0.15 | L9: 0.15 | M9: 0.16 | N9: 0.16 | O9: 0.16 | P9: 0.16 | Q9: 0.17 | R9: 0.17 | S9: 0.17 | T9: 0.17
C11: Depreciation & amortization | D11: CFS | F11: =CF!J21 -> 6980 | G11: =CF!K21 -> 6521 | H11: =CF!L21 -> 6663 | I11: =CF!M21 -> 6772 | J11: =CF!N21 -> 7223 | K11: =J11+J12*5% -> 7710.1 | L11: =K11+K12*5% -> 8275.9098 | M11: =L11+L12*5% -> 8796.9263 | N11: =M11+M12*5% -> 9284.843 | O11: =N11+N12*5% -> 9711.7701 | P11: =O11+O12*5% -> 10078.074 | Q11: =P11+P12*5% -> 10414.523 | R11: =Q11+Q12*5% -> 10751.982 | ... T11: =S11+S12*5% -> 11369.538
C12: CAPEX (IAS 17) | D12: CFS | E12: Further expenditures are expected in 2026-28 with the continued EV transition, stabilising further on. | F12: =-1*SUM(CF!J44:J45) -> 7320 | G12: =-1*SUM(CF!K44:K45) -> 6899 | H12: =-1*SUM(CF!L44:L45) -> 8213 | I12: =-1*SUM(CF!M44:M45) -> 8665 | J12: =-1*SUM(CF!N44:N45) -> 9742 | K12: =K5*K13 -> 11316.196 | L12: =L5*L13 -> 10420.331 | M12: =M5*M13 -> 9758.3332 | N12: =N5*N13 -> 8538.5416 | O12: =O5*O13 -> 7326.0687 | P12: =P5*P13 -> 6728.9941 | Q12: =Q5*Q13 -> 6749.1811 | R12: =R5*R13 -> 6160.1616 | ... T12: =T5*T13 -> 6221.9172
C13: CAPEX (IAS 17) margin, % | D13: Calcs | F13: =F12/F5 -> 0.05467052 | G13: =G12/G5 -> 0.045988121 | H13: =H12/H5 -> 0.053894613 | I13: =I12/I5 -> 0.059514815 | J13: =J12/J5 -> 0.073683574 | K13: 0.09 | L13: 0.085 | M13: 0.08 | N13: 0.07 | O13: 0.06 | P13: 0.055 | Q13: 0.055 | R13: 0.05 | S13: 0.05 | T13: 0.05
C15: Interest paid | D15: Note 29 | E15: In 2024 Mercedes adjusted interest paid for 2023 from 324 to 3068 while not providing notes about the motivation for the adjustment. We accept it and believe that the approach to accounting was changed and will remain the same in the foreseeable future. | F15: 367 | G15: 486 | H15: 3068 | I15: 3902 | J15: 4003 | K15: =K17*K16 -> 4065.8041 | L15: =L17*L16 -> 3743.9279 | M15: =M17*M16 -> 3005.21 | N15: =N17*N16 -> 2191.299 | O15: =O17*O16 -> 1880.1345 | P15: =P17*P16 -> 1381.5229 | Q15: =Q17*Q16 -> 1385.6674 | R15: =R17*R16 -> 1264.7364 | ... T15: =T17*T16 -> 1277.4154
C16: Effective interest rate | D16: Bundesbank IR | E16: According to Bundesbank, interest rates are to remain unchanged from 2025, inflation projected to stabilise around 2%. Geopolitical pressure and energy logistics are expected to stabilise further during the later half of the forecast period. | G16: =G15/(F17+G17)*2 -> 0.0040895321 | H16: =H15/(G17+H17)*2 -> 0.027731077 | I16: =I15/(H17+I17)*2 -> 0.035116929 | J16: =J15/(I17+J17)*2 -> 0.037621473 | K16: 0.035 | L16: 0.035 | M16: 0.03 | N16: 0.025 | O16: 0.025 | P16: 0.02 | Q16: 0.02 | R16: 0.02 | S16: 0.02 | T16: 0.02
C17: Debt | D17: Link | E17: Expected to increase to fuel CAPEX required for continued EV transition. | F17: =BS!J95+BS!J129 -> 125843 | G17: =BS!K95+BS!K129 -> 111837 | H17: =BS!L95+BS!L129 -> 109431 | I17: =BS!M95+BS!M129 -> 112798 | J17: =BS!N95+BS!N129 -> 100006 | K17: =J17*(1+K18) -> 116165.83 | L17: =K17*(1+L18) -> 106969.37 | M17: =L17*(1+M18) -> 100173.67 | N17: =M17*(1+N18) -> 87651.96 | O17: =N17*(1+O18) -> 75205.381 | P17: =O17*(1+P18) -> 69076.143 | Q17: =P17*(1+Q18) -> 69283.371 | R17: =Q17*(1+R18) -> 63236.822 | ... T17: =S17*(1+T18) -> 63870.772
C18: Growth, % | E18: Calculated based on CAPEX changes. | G18: =G12/F12-1 -> -0.057513661 | H18: =H12/G12-1 -> 0.19046239 | I18: =I12/H12-1 -> 0.055034701 | J18: =J12/I12-1 -> 0.12429313 | K18: =K12/J12-1 -> 0.16158861 | L18: =L12/K12-1 -> -0.079166667 | M18: =M12/L12-1 -> -0.063529412 | N18: =N12/M12-1 -> -0.125 | ... T18: =T12/S12-1 -> 0.005
C19: Net change in borrowings | D19: Calcs | G19: =G17-F17 -> -14006 | H19: =H17-G17 -> -2406 | I19: =I17-H17 -> 3367 | J19: =J17-I17 -> -12792 | K19: =K17-J17 -> 16159.831 | L19: =L17-K17 -> -9196.4616 | M19: =M17-L17 -> -6795.7011 | N19: =N17-M17 -> -12521.709 | ... T19: =T17-S17 -> 317.76503
C21: Profit before tax | D21: Link | F21: =PL!J46 -> 15811 | G21: =PL!K46 -> 20304 | H21: =PL!L46 -> 20084 | I21: =PL!M46 -> 14147 | J21: =PL!N46 -> 6284 | K21: =K8-K11-K15 -> 7084.423 | L21: =L8-L11-L15 -> 6368.9812 | M21: =M8-M11-M15 -> 7714.5301 | N21: =N8-N11-N15 -> 8040.5245 | O21: =O8-O11-O15 -> 7944.2785 | P21: =P8-P11-P15 -> 8115.6591 | Q21: =Q8-Q11-Q15 -> 9060.9145 | R21: =R8-R11-R15 -> 8927.8308 | ... T21: =T8-T11-T15 -> 8507.5647
C22: Effective tax rate | D22: Note 10 | E22: According to PwC, German corporate tax rate is planned to decrease from 15% to 10% by 1% a year starting in 2028 and completing in 2032. 0.5% decrease is calculated assuming 40% of Mercedes-Benz Group AG profits are subject to German tax. | F22: =-1*PL!J49/PL!J46 -> 0.30111947 | G22: =-1*PL!K49/PL!K46 -> 0.27063633 | H22: =-1*PL!L49/PL!L46 -> 0.27648875 | I22: =-1*PL!M49/PL!M46 -> 0.26422563 | J22: =-1*PL!N49/PL!N46 -> 0.151655 | K22: 0.3 | L22: =K22 -> 0.3 | M22: =L22-0.5% -> 0.295 | N22: =M22-0.5% -> 0.29 | O22: =N22-0.5% -> 0.285 | P22: =O22-0.5% -> 0.28 | Q22: =P22-0.5% -> 0.275 | R22: =Q22 -> 0.275 | S22: =R22 -> 0.275 | T22: =S22 -> 0.275
C24: Net working capital | D24: Calcs | F24: =F25-F26 -> 52154 | G24: =G25-G26 -> 58829 | H24: =H25-H26 -> 60189 | I24: =I25-I26 -> 61544 | J24: =J25-J26 -> 54117 | K24: =K5/365*K27 -> 50511.958 | L24: =L5/365*L27 -> 49249.159 | M24: =M5/365*M27 -> 49002.914 | N24: =N5/365*N27 -> 49002.914 | O24: =O5/365*O27 -> 49051.916 | P24: =P5/365*P27 -> 49150.02 | Q24: =Q5/365*Q27 -> 49297.47 | R24: =R5/365*R27 -> 49494.66 | ... T24: =T5/365*T27 -> 49990.844
C25: Adj Current assets (operational) | D25: Link | F25: =BS!J48+BS!J51+BS!J54+BS!J66 -> 62809 | G25: =BS!K48+BS!K51+BS!K54+BS!K66 -> 71033 | H25: =BS!L48+BS!L51+BS!L54+BS!L66 -> 73842 | I25: =BS!M48+BS!M51+BS!M54+BS!M66 -> 73561 | J25: =BS!N48+BS!N51+BS!N54+BS!N66 -> 65428
C26: Adj Current liabilities (operational) | D26: Link | F26: =BS!J123+BS!J141 -> 10655 | G26: =BS!K123+BS!K141 -> 12204 | H26: =BS!L123+BS!L141 -> 13653 | I26: =BS!M123+BS!M141 -> 12017 | J26: =BS!N123+BS!N141 -> 11311
C27: NWC turnover, days | D27: Calcs | F27: =F24/F5*365 -> 142.1748 | G27: =G24/G5*365 -> 143.13434 | H27: =H24/H5*365 -> 144.1629 | I27: =I24/I5*365 -> 154.28905 | J27: =J24/J5*365 -> 149.3995 | K27: =AVERAGE(F27:J27) -> 146.63212 | L27: =K27 -> 146.63212 | M27: =L27 -> 146.63212 | N27: =M27 -> 146.63212 | O27: =N27 -> 146.63212 | P27: =O27 -> 146.63212 | Q27: =P27 -> 146.63212 | R27: =Q27 -> 146.63212 | S27: =R27 -> 146.63212 | T27: =S27 -> 146.63212
C28: Δ NWC | D28: Calcs | G28: =G25-F25 -> 8224 | H28: =H25-G25 -> 2809 | I28: =I25-H25 -> -281 | J28: =J25-I25 -> -8133 | K28: =K24-J24 -> -3605.0417 | L28: =L24-K24 -> -1262.799 | M28: =M24-L24 -> -246.2458 | N28: =N24-M24 -> 0 | O28: =O24-N24 -> 49.002914 | P28: =P24-O24 -> 98.103833 | Q28: =Q24-P24 -> 147.45006 | R28: =R24-Q24 -> 197.18988 | ... T28: =T24-S24 -> 248.71067
C31: EBIT * (1-tax) | K31: =(K8-K11)*(1-K22) -> 7805.159 | L31: =(L8-L11)*(1-L22) -> 7079.0364 | M31: =(M8-M11)*(1-M22) -> 7557.4168 | N31: =(N8-N11)*(1-N22) -> 7264.5947 | O31: =(O8-O11)*(1-O22) -> 7024.4553 | P31: =(P8-P11)*(1-P22) -> 6837.971 | Q31: =(Q8-Q11)*(1-Q22) -> 7573.7719 | R31: =(R8-R11)*(1-R22) -> 7389.6113 | ... T31: =(T8-T11)*(1-T22) -> 7094.1106
C32: Depreciation | K32: =K11 -> 7710.1 | L32: =L11 -> 8275.9098 | M32: =M11 -> 8796.9263 | N32: =N11 -> 9284.843 | O32: =O11 -> 9711.7701 | P32: =P11 -> 10078.074 | Q32: =Q11 -> 10414.523 | R32: =R11 -> 10751.982 | ... T32: =T11 -> 11369.538
C33: Δ NWC | K33: =-K28 -> 3605.0417 | L33: =-L28 -> 1262.799 | M33: =-M28 -> 246.2458 | N33: =-N28 -> 0 | O33: =-O28 -> -49.002914 | P33: =-P28 -> -98.103833 | Q33: =-Q28 -> -147.45006 | R33: =-R28 -> -197.18988 | ... T33: =-T28 -> -248.71067
C34: CAPEX | K34: =-K12 -> -11316.196 | L34: =-L12 -> -10420.331 | M34: =-M12 -> -9758.3332 | N34: =-N12 -> -8538.5416 | O34: =-O12 -> -7326.0687 | P34: =-P12 -> -6728.9941 | Q34: =-Q12 -> -6749.1811 | R34: =-R12 -> -6160.1616 | ... T34: =-T12 -> -6221.9172
C35: Free Cash Flow to the Firm | K35: =SUM(K31:K34) -> 7804.1044 | L35: =SUM(L31:L34) -> 6197.4144 | M35: =SUM(M31:M34) -> 6842.2557 | N35: =SUM(N31:N34) -> 8010.8961 | O35: =SUM(O31:O34) -> 9361.1538 | P35: =SUM(P31:P34) -> 10088.947 | Q35: =SUM(Q31:Q34) -> 11091.664 | R35: =SUM(R31:R34) -> 11784.242 | ... T35: =SUM(T31:T34) -> 11993.021
C37: Discount rate (WACC) | D37: =WACC!I11 -> 0.064819449
C38: Discount factor | J38: 1 | K38: =J38/(1+$D$37) -> 0.93912635 | L38: =K38/(1+$D$37) -> 0.8819583 | M38: =L38/(1+$D$37) -> 0.82827027 | N38: =M38/(1+$D$37) -> 0.77785044 | O38: =N38/(1+$D$37) -> 0.73049984 | P38: =O38/(1+$D$37) -> 0.68603165 | Q38: =P38/(1+$D$37) -> 0.6442704 | R38: =Q38/(1+$D$37) -> 0.6050513 | ... T38: =S38/(1+$D$37) -> 0.53363002
C39: Discounted FCFF | K39: =K35*K38 -> 7329.0401 | L39: =L35*L38 -> 5465.8611 | M39: =M35*M38 -> 5667.237 | N39: =N35*N38 -> 6231.279 | O39: =O35*O38 -> 6838.3214 | P39: =P35*P38 -> 6921.3367 | Q39: =Q35*Q38 -> 7146.0307 | R39: =R35*R38 -> 7130.071 | ... T39: =T35*T38 -> 6399.8361
C40: Long-term growth rate | D40: 0.006 | E40: Germany GDP growth rate
C41: Terminal value | T41: =T35*(1+D40)/(D37-D40)*T38 -> 109457.59
C43: Enterprise value | D43: =SUM(K39:T39)+T41 -> 175327.84
C44: Net debt | D44: =Ratios!D7 -> 88640 | E44: As of 31/12/25
C45: Estimated Equity value | D45: =D43-D44 -> 86687.839
C46: Number of shares, mln | D46: =Ratios!D4 -> 962.9037
C47: Estimated share value | D47: =D45/D46 -> 90.027527 | E47: EUR
C49: Free Cash Flow to Equity | K49: =K35-K15*(1-K22)+K19 -> 21117.872 | L49: =L35-L15*(1-L22)+L19 -> -5619.7967 | M49: =M35-M15*(1-M22)+M19 -> -2072.1185 | N49: =N35-N15*(1-N22)+N19 -> -6066.6347 | O49: =O35-O15*(1-O22)+O19 -> -4429.7206 | P49: =P35-P15*(1-P22)+P19 -> 2965.0116 | Q49: =Q35-Q15*(1-Q22)+Q19 -> 10294.284 | R49: =R35-R15*(1-R22)+R19 -> 4820.7594 | ... T49: =T35-T15*(1-T22)+T19 -> 11384.66
C51: Discount rate (Re) | D51: =COE!I10 -> 0.10484757
C52: Discount factor | J52: 1 | K52: =J52/(1+$D$51) -> 0.90510223 | L52: =K52/(1+$D$51) -> 0.81921004 | M52: =L52/(1+$D$51) -> 0.74146883 | N52: =M52/(1+$D$51) -> 0.67110509 | O52: =N52/(1+$D$51) -> 0.60741871 | P52: =O52/(1+$D$51) -> 0.54977603 | Q52: =P52/(1+$D$51) -> 0.49760351 | R52: =Q52/(1+$D$51) -> 0.45038204 | ... T52: =S52/(1+$D$51) -> 0.36895749
C53: Discounted FCFF | K53: =K49*K52 -> 19113.833 | L53: =L49*L52 -> -4603.7939 | M53: =M49*M52 -> -1536.4113 | N53: =N49*N52 -> -4071.3494 | O53: =O49*O52 -> -2690.6952 | P53: =P49*P52 -> 1630.0923 | Q53: =Q49*Q52 -> 5122.4716 | R53: =R49*R52 -> 2171.1834 | ... T53: =T49*T52 -> 4200.4556
...

Sheet 5. DDM

Sheet Dividend Policy Summary
